{
 "cells": [
  {
   "cell_type": "code",
   "execution_count": 1,
   "id": "aea966d2",
   "metadata": {},
   "outputs": [
    {
     "name": "stdout",
     "output_type": "stream",
     "text": [
      "Hello\n"
     ]
    }
   ],
   "source": [
    "print(\"Hello\")"
   ]
  },
  {
   "cell_type": "code",
   "execution_count": null,
   "id": "5fd74171",
   "metadata": {},
   "outputs": [
    {
     "name": "stderr",
     "output_type": "stream",
     "text": [
      "ERROR:root:Internal Python error in the inspect module.\n",
      "Below is the traceback from this internal error.\n",
      "\n",
      "ERROR:root:Internal Python error in the inspect module.\n",
      "Below is the traceback from this internal error.\n",
      "\n",
      "ERROR:root:Internal Python error in the inspect module.\n",
      "Below is the traceback from this internal error.\n",
      "\n"
     ]
    },
    {
     "name": "stdout",
     "output_type": "stream",
     "text": [
      "Traceback (most recent call last):\n",
      "  File \"C:\\Users\\fakthar\\AppData\\Local\\anaconda3\\envs\\mytfenv\\lib\\site-packages\\IPython\\core\\interactiveshell.py\", line 3553, in run_code\n",
      "    exec(code_obj, self.user_global_ns, self.user_ns)\n",
      "  File \"C:\\Users\\fakthar\\AppData\\Local\\Temp\\ipykernel_7248\\3793406994.py\", line 1, in <module>\n",
      "    import tensorflow as tf\n",
      "  File \"C:\\Users\\fakthar\\AppData\\Local\\anaconda3\\envs\\mytfenv\\lib\\site-packages\\tensorflow\\__init__.py\", line 98, in <module>\n",
      "    from tensorflow_core import *\n",
      "  File \"C:\\Users\\fakthar\\AppData\\Local\\anaconda3\\envs\\mytfenv\\lib\\site-packages\\tensorflow_core\\__init__.py\", line 40, in <module>\n",
      "    from tensorflow.python.tools import module_util as _module_util\n",
      "  File \"<frozen importlib._bootstrap>\", line 983, in _find_and_load\n",
      "  File \"<frozen importlib._bootstrap>\", line 959, in _find_and_load_unlocked\n",
      "  File \"C:\\Users\\fakthar\\AppData\\Local\\anaconda3\\envs\\mytfenv\\lib\\site-packages\\tensorflow\\__init__.py\", line 50, in __getattr__\n",
      "    module = self._load()\n",
      "  File \"C:\\Users\\fakthar\\AppData\\Local\\anaconda3\\envs\\mytfenv\\lib\\site-packages\\tensorflow\\__init__.py\", line 44, in _load\n",
      "    module = _importlib.import_module(self.__name__)\n",
      "  File \"C:\\Users\\fakthar\\AppData\\Local\\anaconda3\\envs\\mytfenv\\lib\\importlib\\__init__.py\", line 127, in import_module\n",
      "    return _bootstrap._gcd_import(name[level:], package, level)\n",
      "  File \"C:\\Users\\fakthar\\AppData\\Local\\anaconda3\\envs\\mytfenv\\lib\\site-packages\\tensorflow_core\\python\\__init__.py\", line 52, in <module>\n",
      "    from tensorflow.core.framework.graph_pb2 import *\n",
      "  File \"C:\\Users\\fakthar\\AppData\\Local\\anaconda3\\envs\\mytfenv\\lib\\site-packages\\tensorflow_core\\core\\framework\\graph_pb2.py\", line 16, in <module>\n",
      "    from tensorflow.core.framework import node_def_pb2 as tensorflow_dot_core_dot_framework_dot_node__def__pb2\n",
      "  File \"C:\\Users\\fakthar\\AppData\\Local\\anaconda3\\envs\\mytfenv\\lib\\site-packages\\tensorflow_core\\core\\framework\\node_def_pb2.py\", line 16, in <module>\n",
      "    from tensorflow.core.framework import attr_value_pb2 as tensorflow_dot_core_dot_framework_dot_attr__value__pb2\n",
      "  File \"C:\\Users\\fakthar\\AppData\\Local\\anaconda3\\envs\\mytfenv\\lib\\site-packages\\tensorflow_core\\core\\framework\\attr_value_pb2.py\", line 16, in <module>\n",
      "    from tensorflow.core.framework import tensor_pb2 as tensorflow_dot_core_dot_framework_dot_tensor__pb2\n",
      "  File \"C:\\Users\\fakthar\\AppData\\Local\\anaconda3\\envs\\mytfenv\\lib\\site-packages\\tensorflow_core\\core\\framework\\tensor_pb2.py\", line 16, in <module>\n",
      "    from tensorflow.core.framework import resource_handle_pb2 as tensorflow_dot_core_dot_framework_dot_resource__handle__pb2\n",
      "  File \"C:\\Users\\fakthar\\AppData\\Local\\anaconda3\\envs\\mytfenv\\lib\\site-packages\\tensorflow_core\\core\\framework\\resource_handle_pb2.py\", line 16, in <module>\n",
      "    from tensorflow.core.framework import tensor_shape_pb2 as tensorflow_dot_core_dot_framework_dot_tensor__shape__pb2\n",
      "  File \"C:\\Users\\fakthar\\AppData\\Local\\anaconda3\\envs\\mytfenv\\lib\\site-packages\\tensorflow_core\\core\\framework\\tensor_shape_pb2.py\", line 42, in <module>\n",
      "    serialized_options=None, file=DESCRIPTOR),\n",
      "  File \"C:\\Users\\fakthar\\AppData\\Local\\anaconda3\\envs\\mytfenv\\lib\\site-packages\\google\\protobuf\\descriptor.py\", line 561, in __new__\n",
      "    _message.Message._CheckCalledFromGeneratedFile()\n",
      "TypeError: Descriptors cannot not be created directly.\n",
      "If this call came from a _pb2.py file, your generated code is out of date and must be regenerated with protoc >= 3.19.0.\n",
      "If you cannot immediately regenerate your protos, some other possible workarounds are:\n",
      " 1. Downgrade the protobuf package to 3.20.x or lower.\n",
      " 2. Set PROTOCOL_BUFFERS_PYTHON_IMPLEMENTATION=python (but this will use pure-Python parsing and will be much slower).\n",
      "\n",
      "More information: https://developers.google.com/protocol-buffers/docs/news/2022-05-06#python-updates\n",
      "\n",
      "During handling of the above exception, another exception occurred:\n",
      "\n",
      "Traceback (most recent call last):\n",
      "  File \"C:\\Users\\fakthar\\AppData\\Local\\anaconda3\\envs\\mytfenv\\lib\\site-packages\\IPython\\core\\interactiveshell.py\", line 2099, in showtraceback\n",
      "    stb = value._render_traceback_()\n",
      "AttributeError: 'TypeError' object has no attribute '_render_traceback_'\n",
      "\n",
      "During handling of the above exception, another exception occurred:\n",
      "\n",
      "Traceback (most recent call last):\n",
      "  File \"C:\\Users\\fakthar\\AppData\\Local\\anaconda3\\envs\\mytfenv\\lib\\site-packages\\IPython\\core\\ultratb.py\", line 1101, in get_records\n",
      "    return _fixed_getinnerframes(etb, number_of_lines_of_context, tb_offset)\n",
      "  File \"C:\\Users\\fakthar\\AppData\\Local\\anaconda3\\envs\\mytfenv\\lib\\site-packages\\IPython\\core\\ultratb.py\", line 248, in wrapped\n",
      "    return f(*args, **kwargs)\n",
      "  File \"C:\\Users\\fakthar\\AppData\\Local\\anaconda3\\envs\\mytfenv\\lib\\site-packages\\IPython\\core\\ultratb.py\", line 281, in _fixed_getinnerframes\n",
      "    records = fix_frame_records_filenames(inspect.getinnerframes(etb, context))\n",
      "  File \"C:\\Users\\fakthar\\AppData\\Local\\anaconda3\\envs\\mytfenv\\lib\\inspect.py\", line 1500, in getinnerframes\n",
      "    frameinfo = (tb.tb_frame,) + getframeinfo(tb, context)\n",
      "  File \"C:\\Users\\fakthar\\AppData\\Local\\anaconda3\\envs\\mytfenv\\lib\\inspect.py\", line 1458, in getframeinfo\n",
      "    filename = getsourcefile(frame) or getfile(frame)\n",
      "  File \"C:\\Users\\fakthar\\AppData\\Local\\anaconda3\\envs\\mytfenv\\lib\\inspect.py\", line 696, in getsourcefile\n",
      "    if getattr(getmodule(object, filename), '__loader__', None) is not None:\n",
      "  File \"C:\\Users\\fakthar\\AppData\\Local\\anaconda3\\envs\\mytfenv\\lib\\inspect.py\", line 733, in getmodule\n",
      "    if ismodule(module) and hasattr(module, '__file__'):\n",
      "  File \"C:\\Users\\fakthar\\AppData\\Local\\anaconda3\\envs\\mytfenv\\lib\\site-packages\\tensorflow\\__init__.py\", line 50, in __getattr__\n",
      "    module = self._load()\n",
      "  File \"C:\\Users\\fakthar\\AppData\\Local\\anaconda3\\envs\\mytfenv\\lib\\site-packages\\tensorflow\\__init__.py\", line 44, in _load\n",
      "    module = _importlib.import_module(self.__name__)\n",
      "  File \"C:\\Users\\fakthar\\AppData\\Local\\anaconda3\\envs\\mytfenv\\lib\\importlib\\__init__.py\", line 127, in import_module\n",
      "    return _bootstrap._gcd_import(name[level:], package, level)\n",
      "  File \"<frozen importlib._bootstrap>\", line 1006, in _gcd_import\n",
      "  File \"<frozen importlib._bootstrap>\", line 983, in _find_and_load\n",
      "  File \"<frozen importlib._bootstrap>\", line 953, in _find_and_load_unlocked\n",
      "  File \"<frozen importlib._bootstrap>\", line 219, in _call_with_frames_removed\n",
      "  File \"<frozen importlib._bootstrap>\", line 1006, in _gcd_import\n",
      "  File \"<frozen importlib._bootstrap>\", line 983, in _find_and_load\n",
      "  File \"<frozen importlib._bootstrap>\", line 967, in _find_and_load_unlocked\n",
      "  File \"<frozen importlib._bootstrap>\", line 677, in _load_unlocked\n",
      "  File \"<frozen importlib._bootstrap_external>\", line 728, in exec_module\n",
      "  File \"<frozen importlib._bootstrap>\", line 219, in _call_with_frames_removed\n",
      "  File \"C:\\Users\\fakthar\\AppData\\Local\\anaconda3\\envs\\mytfenv\\lib\\site-packages\\tensorflow_core\\__init__.py\", line 42, in <module>\n",
      "    from . _api.v2 import audio\n",
      "  File \"C:\\Users\\fakthar\\AppData\\Local\\anaconda3\\envs\\mytfenv\\lib\\site-packages\\tensorflow_core\\_api\\v2\\audio\\__init__.py\", line 10, in <module>\n",
      "    from tensorflow.python.ops.gen_audio_ops import decode_wav\n",
      "  File \"C:\\Users\\fakthar\\AppData\\Local\\anaconda3\\envs\\mytfenv\\lib\\site-packages\\tensorflow_core\\python\\ops\\gen_audio_ops.py\", line 10, in <module>\n",
      "    from tensorflow.python.eager import context as _context\n",
      "  File \"C:\\Users\\fakthar\\AppData\\Local\\anaconda3\\envs\\mytfenv\\lib\\site-packages\\tensorflow_core\\python\\eager\\context.py\", line 29, in <module>\n",
      "    from tensorflow.core.protobuf import config_pb2\n",
      "  File \"C:\\Users\\fakthar\\AppData\\Local\\anaconda3\\envs\\mytfenv\\lib\\site-packages\\tensorflow_core\\core\\protobuf\\config_pb2.py\", line 16, in <module>\n",
      "    from tensorflow.core.framework import cost_graph_pb2 as tensorflow_dot_core_dot_framework_dot_cost__graph__pb2\n",
      "  File \"C:\\Users\\fakthar\\AppData\\Local\\anaconda3\\envs\\mytfenv\\lib\\site-packages\\tensorflow_core\\core\\framework\\cost_graph_pb2.py\", line 16, in <module>\n",
      "    from tensorflow.core.framework import tensor_shape_pb2 as tensorflow_dot_core_dot_framework_dot_tensor__shape__pb2\n",
      "  File \"C:\\Users\\fakthar\\AppData\\Local\\anaconda3\\envs\\mytfenv\\lib\\site-packages\\tensorflow_core\\core\\framework\\tensor_shape_pb2.py\", line 42, in <module>\n",
      "    serialized_options=None, file=DESCRIPTOR),\n",
      "  File \"C:\\Users\\fakthar\\AppData\\Local\\anaconda3\\envs\\mytfenv\\lib\\site-packages\\google\\protobuf\\descriptor.py\", line 561, in __new__\n",
      "    _message.Message._CheckCalledFromGeneratedFile()\n",
      "TypeError: Descriptors cannot not be created directly.\n",
      "If this call came from a _pb2.py file, your generated code is out of date and must be regenerated with protoc >= 3.19.0.\n",
      "If you cannot immediately regenerate your protos, some other possible workarounds are:\n",
      " 1. Downgrade the protobuf package to 3.20.x or lower.\n",
      " 2. Set PROTOCOL_BUFFERS_PYTHON_IMPLEMENTATION=python (but this will use pure-Python parsing and will be much slower).\n",
      "\n",
      "More information: https://developers.google.com/protocol-buffers/docs/news/2022-05-06#python-updates\n",
      "Traceback (most recent call last):\n",
      "  File \"C:\\Users\\fakthar\\AppData\\Local\\anaconda3\\envs\\mytfenv\\lib\\site-packages\\IPython\\core\\interactiveshell.py\", line 3553, in run_code\n",
      "    exec(code_obj, self.user_global_ns, self.user_ns)\n",
      "  File \"C:\\Users\\fakthar\\AppData\\Local\\Temp\\ipykernel_7248\\3793406994.py\", line 1, in <module>\n",
      "    import tensorflow as tf\n",
      "  File \"C:\\Users\\fakthar\\AppData\\Local\\anaconda3\\envs\\mytfenv\\lib\\site-packages\\tensorflow\\__init__.py\", line 98, in <module>\n",
      "    from tensorflow_core import *\n",
      "  File \"C:\\Users\\fakthar\\AppData\\Local\\anaconda3\\envs\\mytfenv\\lib\\site-packages\\tensorflow_core\\__init__.py\", line 40, in <module>\n",
      "    from tensorflow.python.tools import module_util as _module_util\n",
      "  File \"<frozen importlib._bootstrap>\", line 983, in _find_and_load\n",
      "  File \"<frozen importlib._bootstrap>\", line 959, in _find_and_load_unlocked\n",
      "  File \"C:\\Users\\fakthar\\AppData\\Local\\anaconda3\\envs\\mytfenv\\lib\\site-packages\\tensorflow\\__init__.py\", line 50, in __getattr__\n",
      "    module = self._load()\n",
      "  File \"C:\\Users\\fakthar\\AppData\\Local\\anaconda3\\envs\\mytfenv\\lib\\site-packages\\tensorflow\\__init__.py\", line 44, in _load\n",
      "    module = _importlib.import_module(self.__name__)\n",
      "  File \"C:\\Users\\fakthar\\AppData\\Local\\anaconda3\\envs\\mytfenv\\lib\\importlib\\__init__.py\", line 127, in import_module\n",
      "    return _bootstrap._gcd_import(name[level:], package, level)\n",
      "  File \"C:\\Users\\fakthar\\AppData\\Local\\anaconda3\\envs\\mytfenv\\lib\\site-packages\\tensorflow_core\\python\\__init__.py\", line 52, in <module>\n",
      "    from tensorflow.core.framework.graph_pb2 import *\n",
      "  File \"C:\\Users\\fakthar\\AppData\\Local\\anaconda3\\envs\\mytfenv\\lib\\site-packages\\tensorflow_core\\core\\framework\\graph_pb2.py\", line 16, in <module>\n",
      "    from tensorflow.core.framework import node_def_pb2 as tensorflow_dot_core_dot_framework_dot_node__def__pb2\n",
      "  File \"C:\\Users\\fakthar\\AppData\\Local\\anaconda3\\envs\\mytfenv\\lib\\site-packages\\tensorflow_core\\core\\framework\\node_def_pb2.py\", line 16, in <module>\n",
      "    from tensorflow.core.framework import attr_value_pb2 as tensorflow_dot_core_dot_framework_dot_attr__value__pb2\n",
      "  File \"C:\\Users\\fakthar\\AppData\\Local\\anaconda3\\envs\\mytfenv\\lib\\site-packages\\tensorflow_core\\core\\framework\\attr_value_pb2.py\", line 16, in <module>\n",
      "    from tensorflow.core.framework import tensor_pb2 as tensorflow_dot_core_dot_framework_dot_tensor__pb2\n",
      "  File \"C:\\Users\\fakthar\\AppData\\Local\\anaconda3\\envs\\mytfenv\\lib\\site-packages\\tensorflow_core\\core\\framework\\tensor_pb2.py\", line 16, in <module>\n",
      "    from tensorflow.core.framework import resource_handle_pb2 as tensorflow_dot_core_dot_framework_dot_resource__handle__pb2\n",
      "  File \"C:\\Users\\fakthar\\AppData\\Local\\anaconda3\\envs\\mytfenv\\lib\\site-packages\\tensorflow_core\\core\\framework\\resource_handle_pb2.py\", line 16, in <module>\n",
      "    from tensorflow.core.framework import tensor_shape_pb2 as tensorflow_dot_core_dot_framework_dot_tensor__shape__pb2\n",
      "  File \"C:\\Users\\fakthar\\AppData\\Local\\anaconda3\\envs\\mytfenv\\lib\\site-packages\\tensorflow_core\\core\\framework\\tensor_shape_pb2.py\", line 42, in <module>\n",
      "    serialized_options=None, file=DESCRIPTOR),\n",
      "  File \"C:\\Users\\fakthar\\AppData\\Local\\anaconda3\\envs\\mytfenv\\lib\\site-packages\\google\\protobuf\\descriptor.py\", line 561, in __new__\n",
      "    _message.Message._CheckCalledFromGeneratedFile()\n",
      "TypeError: Descriptors cannot not be created directly.\n",
      "If this call came from a _pb2.py file, your generated code is out of date and must be regenerated with protoc >= 3.19.0.\n",
      "If you cannot immediately regenerate your protos, some other possible workarounds are:\n",
      " 1. Downgrade the protobuf package to 3.20.x or lower.\n",
      " 2. Set PROTOCOL_BUFFERS_PYTHON_IMPLEMENTATION=python (but this will use pure-Python parsing and will be much slower).\n",
      "\n",
      "More information: https://developers.google.com/protocol-buffers/docs/news/2022-05-06#python-updates\n",
      "\n",
      "During handling of the above exception, another exception occurred:\n",
      "\n",
      "Traceback (most recent call last):\n",
      "  File \"C:\\Users\\fakthar\\AppData\\Local\\anaconda3\\envs\\mytfenv\\lib\\site-packages\\IPython\\core\\interactiveshell.py\", line 2099, in showtraceback\n",
      "    stb = value._render_traceback_()\n",
      "AttributeError: 'TypeError' object has no attribute '_render_traceback_'\n",
      "\n",
      "During handling of the above exception, another exception occurred:\n",
      "\n",
      "Traceback (most recent call last):\n",
      "  File \"C:\\Users\\fakthar\\AppData\\Local\\anaconda3\\envs\\mytfenv\\lib\\site-packages\\IPython\\core\\interactiveshell.py\", line 3473, in run_ast_nodes\n",
      "    if (await self.run_code(code, result,  async_=asy)):\n",
      "  File \"C:\\Users\\fakthar\\AppData\\Local\\anaconda3\\envs\\mytfenv\\lib\\site-packages\\IPython\\core\\interactiveshell.py\", line 3575, in run_code\n",
      "    self.showtraceback(running_compiled_code=True)\n",
      "  File \"C:\\Users\\fakthar\\AppData\\Local\\anaconda3\\envs\\mytfenv\\lib\\site-packages\\IPython\\core\\interactiveshell.py\", line 2102, in showtraceback\n",
      "    value, tb, tb_offset=tb_offset)\n",
      "  File \"C:\\Users\\fakthar\\AppData\\Local\\anaconda3\\envs\\mytfenv\\lib\\site-packages\\IPython\\core\\ultratb.py\", line 1368, in structured_traceback\n",
      "    self, etype, value, tb, tb_offset, number_of_lines_of_context)\n",
      "  File \"C:\\Users\\fakthar\\AppData\\Local\\anaconda3\\envs\\mytfenv\\lib\\site-packages\\IPython\\core\\ultratb.py\", line 1268, in structured_traceback\n",
      "    self, etype, value, tb, tb_offset, number_of_lines_of_context\n",
      "  File \"C:\\Users\\fakthar\\AppData\\Local\\anaconda3\\envs\\mytfenv\\lib\\site-packages\\IPython\\core\\ultratb.py\", line 1125, in structured_traceback\n",
      "    tb_offset)\n",
      "  File \"C:\\Users\\fakthar\\AppData\\Local\\anaconda3\\envs\\mytfenv\\lib\\site-packages\\IPython\\core\\ultratb.py\", line 1082, in format_exception_as_a_whole\n",
      "    last_unique, recursion_repeat = find_recursion(orig_etype, evalue, records)\n",
      "  File \"C:\\Users\\fakthar\\AppData\\Local\\anaconda3\\envs\\mytfenv\\lib\\site-packages\\IPython\\core\\ultratb.py\", line 382, in find_recursion\n",
      "    return len(records), 0\n",
      "TypeError: object of type 'NoneType' has no len()\n",
      "\n",
      "During handling of the above exception, another exception occurred:\n",
      "\n",
      "Traceback (most recent call last):\n",
      "  File \"C:\\Users\\fakthar\\AppData\\Local\\anaconda3\\envs\\mytfenv\\lib\\site-packages\\IPython\\core\\interactiveshell.py\", line 2099, in showtraceback\n",
      "    stb = value._render_traceback_()\n",
      "AttributeError: 'TypeError' object has no attribute '_render_traceback_'\n",
      "\n",
      "During handling of the above exception, another exception occurred:\n",
      "\n",
      "Traceback (most recent call last):\n",
      "  File \"C:\\Users\\fakthar\\AppData\\Local\\anaconda3\\envs\\mytfenv\\lib\\site-packages\\IPython\\core\\ultratb.py\", line 1101, in get_records\n",
      "    return _fixed_getinnerframes(etb, number_of_lines_of_context, tb_offset)\n",
      "  File \"C:\\Users\\fakthar\\AppData\\Local\\anaconda3\\envs\\mytfenv\\lib\\site-packages\\IPython\\core\\ultratb.py\", line 248, in wrapped\n",
      "    return f(*args, **kwargs)\n",
      "  File \"C:\\Users\\fakthar\\AppData\\Local\\anaconda3\\envs\\mytfenv\\lib\\site-packages\\IPython\\core\\ultratb.py\", line 281, in _fixed_getinnerframes\n",
      "    records = fix_frame_records_filenames(inspect.getinnerframes(etb, context))\n",
      "  File \"C:\\Users\\fakthar\\AppData\\Local\\anaconda3\\envs\\mytfenv\\lib\\inspect.py\", line 1500, in getinnerframes\n",
      "    frameinfo = (tb.tb_frame,) + getframeinfo(tb, context)\n",
      "  File \"C:\\Users\\fakthar\\AppData\\Local\\anaconda3\\envs\\mytfenv\\lib\\inspect.py\", line 1458, in getframeinfo\n",
      "    filename = getsourcefile(frame) or getfile(frame)\n",
      "  File \"C:\\Users\\fakthar\\AppData\\Local\\anaconda3\\envs\\mytfenv\\lib\\inspect.py\", line 696, in getsourcefile\n",
      "    if getattr(getmodule(object, filename), '__loader__', None) is not None:\n",
      "  File \"C:\\Users\\fakthar\\AppData\\Local\\anaconda3\\envs\\mytfenv\\lib\\inspect.py\", line 733, in getmodule\n",
      "    if ismodule(module) and hasattr(module, '__file__'):\n",
      "  File \"C:\\Users\\fakthar\\AppData\\Local\\anaconda3\\envs\\mytfenv\\lib\\site-packages\\tensorflow\\__init__.py\", line 50, in __getattr__\n",
      "    module = self._load()\n",
      "  File \"C:\\Users\\fakthar\\AppData\\Local\\anaconda3\\envs\\mytfenv\\lib\\site-packages\\tensorflow\\__init__.py\", line 44, in _load\n",
      "    module = _importlib.import_module(self.__name__)\n",
      "  File \"C:\\Users\\fakthar\\AppData\\Local\\anaconda3\\envs\\mytfenv\\lib\\importlib\\__init__.py\", line 127, in import_module\n",
      "    return _bootstrap._gcd_import(name[level:], package, level)\n",
      "  File \"<frozen importlib._bootstrap>\", line 1006, in _gcd_import\n",
      "  File \"<frozen importlib._bootstrap>\", line 983, in _find_and_load\n",
      "  File \"<frozen importlib._bootstrap>\", line 953, in _find_and_load_unlocked\n",
      "  File \"<frozen importlib._bootstrap>\", line 219, in _call_with_frames_removed\n",
      "  File \"<frozen importlib._bootstrap>\", line 1006, in _gcd_import\n",
      "  File \"<frozen importlib._bootstrap>\", line 983, in _find_and_load\n",
      "  File \"<frozen importlib._bootstrap>\", line 967, in _find_and_load_unlocked\n",
      "  File \"<frozen importlib._bootstrap>\", line 677, in _load_unlocked\n",
      "  File \"<frozen importlib._bootstrap_external>\", line 728, in exec_module\n",
      "  File \"<frozen importlib._bootstrap>\", line 219, in _call_with_frames_removed\n",
      "  File \"C:\\Users\\fakthar\\AppData\\Local\\anaconda3\\envs\\mytfenv\\lib\\site-packages\\tensorflow_core\\__init__.py\", line 42, in <module>\n",
      "    from . _api.v2 import audio\n",
      "  File \"C:\\Users\\fakthar\\AppData\\Local\\anaconda3\\envs\\mytfenv\\lib\\site-packages\\tensorflow_core\\_api\\v2\\audio\\__init__.py\", line 10, in <module>\n",
      "    from tensorflow.python.ops.gen_audio_ops import decode_wav\n",
      "  File \"C:\\Users\\fakthar\\AppData\\Local\\anaconda3\\envs\\mytfenv\\lib\\site-packages\\tensorflow_core\\python\\ops\\gen_audio_ops.py\", line 10, in <module>\n",
      "    from tensorflow.python.eager import context as _context\n",
      "  File \"C:\\Users\\fakthar\\AppData\\Local\\anaconda3\\envs\\mytfenv\\lib\\site-packages\\tensorflow_core\\python\\eager\\context.py\", line 29, in <module>\n",
      "    from tensorflow.core.protobuf import config_pb2\n",
      "  File \"C:\\Users\\fakthar\\AppData\\Local\\anaconda3\\envs\\mytfenv\\lib\\site-packages\\tensorflow_core\\core\\protobuf\\config_pb2.py\", line 16, in <module>\n",
      "    from tensorflow.core.framework import cost_graph_pb2 as tensorflow_dot_core_dot_framework_dot_cost__graph__pb2\n",
      "  File \"C:\\Users\\fakthar\\AppData\\Local\\anaconda3\\envs\\mytfenv\\lib\\site-packages\\tensorflow_core\\core\\framework\\cost_graph_pb2.py\", line 16, in <module>\n",
      "    from tensorflow.core.framework import tensor_shape_pb2 as tensorflow_dot_core_dot_framework_dot_tensor__shape__pb2\n",
      "  File \"C:\\Users\\fakthar\\AppData\\Local\\anaconda3\\envs\\mytfenv\\lib\\site-packages\\tensorflow_core\\core\\framework\\tensor_shape_pb2.py\", line 42, in <module>\n",
      "    serialized_options=None, file=DESCRIPTOR),\n",
      "  File \"C:\\Users\\fakthar\\AppData\\Local\\anaconda3\\envs\\mytfenv\\lib\\site-packages\\google\\protobuf\\descriptor.py\", line 561, in __new__\n",
      "    _message.Message._CheckCalledFromGeneratedFile()\n",
      "TypeError: Descriptors cannot not be created directly.\n",
      "If this call came from a _pb2.py file, your generated code is out of date and must be regenerated with protoc >= 3.19.0.\n",
      "If you cannot immediately regenerate your protos, some other possible workarounds are:\n",
      " 1. Downgrade the protobuf package to 3.20.x or lower.\n",
      " 2. Set PROTOCOL_BUFFERS_PYTHON_IMPLEMENTATION=python (but this will use pure-Python parsing and will be much slower).\n",
      "\n",
      "More information: https://developers.google.com/protocol-buffers/docs/news/2022-05-06#python-updates\n",
      "Traceback (most recent call last):\n",
      "  File \"C:\\Users\\fakthar\\AppData\\Local\\anaconda3\\envs\\mytfenv\\lib\\site-packages\\IPython\\core\\interactiveshell.py\", line 3553, in run_code\n",
      "    exec(code_obj, self.user_global_ns, self.user_ns)\n",
      "  File \"C:\\Users\\fakthar\\AppData\\Local\\Temp\\ipykernel_7248\\3793406994.py\", line 1, in <module>\n",
      "    import tensorflow as tf\n",
      "  File \"C:\\Users\\fakthar\\AppData\\Local\\anaconda3\\envs\\mytfenv\\lib\\site-packages\\tensorflow\\__init__.py\", line 98, in <module>\n",
      "    from tensorflow_core import *\n",
      "  File \"C:\\Users\\fakthar\\AppData\\Local\\anaconda3\\envs\\mytfenv\\lib\\site-packages\\tensorflow_core\\__init__.py\", line 40, in <module>\n",
      "    from tensorflow.python.tools import module_util as _module_util\n",
      "  File \"<frozen importlib._bootstrap>\", line 983, in _find_and_load\n",
      "  File \"<frozen importlib._bootstrap>\", line 959, in _find_and_load_unlocked\n",
      "  File \"C:\\Users\\fakthar\\AppData\\Local\\anaconda3\\envs\\mytfenv\\lib\\site-packages\\tensorflow\\__init__.py\", line 50, in __getattr__\n",
      "    module = self._load()\n",
      "  File \"C:\\Users\\fakthar\\AppData\\Local\\anaconda3\\envs\\mytfenv\\lib\\site-packages\\tensorflow\\__init__.py\", line 44, in _load\n",
      "    module = _importlib.import_module(self.__name__)\n",
      "  File \"C:\\Users\\fakthar\\AppData\\Local\\anaconda3\\envs\\mytfenv\\lib\\importlib\\__init__.py\", line 127, in import_module\n",
      "    return _bootstrap._gcd_import(name[level:], package, level)\n",
      "  File \"C:\\Users\\fakthar\\AppData\\Local\\anaconda3\\envs\\mytfenv\\lib\\site-packages\\tensorflow_core\\python\\__init__.py\", line 52, in <module>\n",
      "    from tensorflow.core.framework.graph_pb2 import *\n",
      "  File \"C:\\Users\\fakthar\\AppData\\Local\\anaconda3\\envs\\mytfenv\\lib\\site-packages\\tensorflow_core\\core\\framework\\graph_pb2.py\", line 16, in <module>\n",
      "    from tensorflow.core.framework import node_def_pb2 as tensorflow_dot_core_dot_framework_dot_node__def__pb2\n",
      "  File \"C:\\Users\\fakthar\\AppData\\Local\\anaconda3\\envs\\mytfenv\\lib\\site-packages\\tensorflow_core\\core\\framework\\node_def_pb2.py\", line 16, in <module>\n",
      "    from tensorflow.core.framework import attr_value_pb2 as tensorflow_dot_core_dot_framework_dot_attr__value__pb2\n",
      "  File \"C:\\Users\\fakthar\\AppData\\Local\\anaconda3\\envs\\mytfenv\\lib\\site-packages\\tensorflow_core\\core\\framework\\attr_value_pb2.py\", line 16, in <module>\n",
      "    from tensorflow.core.framework import tensor_pb2 as tensorflow_dot_core_dot_framework_dot_tensor__pb2\n",
      "  File \"C:\\Users\\fakthar\\AppData\\Local\\anaconda3\\envs\\mytfenv\\lib\\site-packages\\tensorflow_core\\core\\framework\\tensor_pb2.py\", line 16, in <module>\n",
      "    from tensorflow.core.framework import resource_handle_pb2 as tensorflow_dot_core_dot_framework_dot_resource__handle__pb2\n",
      "  File \"C:\\Users\\fakthar\\AppData\\Local\\anaconda3\\envs\\mytfenv\\lib\\site-packages\\tensorflow_core\\core\\framework\\resource_handle_pb2.py\", line 16, in <module>\n",
      "    from tensorflow.core.framework import tensor_shape_pb2 as tensorflow_dot_core_dot_framework_dot_tensor__shape__pb2\n",
      "  File \"C:\\Users\\fakthar\\AppData\\Local\\anaconda3\\envs\\mytfenv\\lib\\site-packages\\tensorflow_core\\core\\framework\\tensor_shape_pb2.py\", line 42, in <module>\n",
      "    serialized_options=None, file=DESCRIPTOR),\n",
      "  File \"C:\\Users\\fakthar\\AppData\\Local\\anaconda3\\envs\\mytfenv\\lib\\site-packages\\google\\protobuf\\descriptor.py\", line 561, in __new__\n",
      "    _message.Message._CheckCalledFromGeneratedFile()\n",
      "TypeError: Descriptors cannot not be created directly.\n",
      "If this call came from a _pb2.py file, your generated code is out of date and must be regenerated with protoc >= 3.19.0.\n",
      "If you cannot immediately regenerate your protos, some other possible workarounds are:\n",
      " 1. Downgrade the protobuf package to 3.20.x or lower.\n",
      " 2. Set PROTOCOL_BUFFERS_PYTHON_IMPLEMENTATION=python (but this will use pure-Python parsing and will be much slower).\n",
      "\n",
      "More information: https://developers.google.com/protocol-buffers/docs/news/2022-05-06#python-updates\n",
      "\n",
      "During handling of the above exception, another exception occurred:\n",
      "\n",
      "Traceback (most recent call last):\n",
      "  File \"C:\\Users\\fakthar\\AppData\\Local\\anaconda3\\envs\\mytfenv\\lib\\site-packages\\IPython\\core\\interactiveshell.py\", line 2099, in showtraceback\n",
      "    stb = value._render_traceback_()\n",
      "AttributeError: 'TypeError' object has no attribute '_render_traceback_'\n",
      "\n",
      "During handling of the above exception, another exception occurred:\n",
      "\n",
      "Traceback (most recent call last):\n",
      "  File \"C:\\Users\\fakthar\\AppData\\Local\\anaconda3\\envs\\mytfenv\\lib\\site-packages\\IPython\\core\\interactiveshell.py\", line 3473, in run_ast_nodes\n",
      "    if (await self.run_code(code, result,  async_=asy)):\n",
      "  File \"C:\\Users\\fakthar\\AppData\\Local\\anaconda3\\envs\\mytfenv\\lib\\site-packages\\IPython\\core\\interactiveshell.py\", line 3575, in run_code\n",
      "    self.showtraceback(running_compiled_code=True)\n",
      "  File \"C:\\Users\\fakthar\\AppData\\Local\\anaconda3\\envs\\mytfenv\\lib\\site-packages\\IPython\\core\\interactiveshell.py\", line 2102, in showtraceback\n",
      "    value, tb, tb_offset=tb_offset)\n",
      "  File \"C:\\Users\\fakthar\\AppData\\Local\\anaconda3\\envs\\mytfenv\\lib\\site-packages\\IPython\\core\\ultratb.py\", line 1368, in structured_traceback\n",
      "    self, etype, value, tb, tb_offset, number_of_lines_of_context)\n",
      "  File \"C:\\Users\\fakthar\\AppData\\Local\\anaconda3\\envs\\mytfenv\\lib\\site-packages\\IPython\\core\\ultratb.py\", line 1268, in structured_traceback\n",
      "    self, etype, value, tb, tb_offset, number_of_lines_of_context\n",
      "  File \"C:\\Users\\fakthar\\AppData\\Local\\anaconda3\\envs\\mytfenv\\lib\\site-packages\\IPython\\core\\ultratb.py\", line 1125, in structured_traceback\n",
      "    tb_offset)\n",
      "  File \"C:\\Users\\fakthar\\AppData\\Local\\anaconda3\\envs\\mytfenv\\lib\\site-packages\\IPython\\core\\ultratb.py\", line 1082, in format_exception_as_a_whole\n",
      "    last_unique, recursion_repeat = find_recursion(orig_etype, evalue, records)\n",
      "  File \"C:\\Users\\fakthar\\AppData\\Local\\anaconda3\\envs\\mytfenv\\lib\\site-packages\\IPython\\core\\ultratb.py\", line 382, in find_recursion\n",
      "    return len(records), 0\n",
      "TypeError: object of type 'NoneType' has no len()\n",
      "\n",
      "During handling of the above exception, another exception occurred:\n",
      "\n",
      "Traceback (most recent call last):\n",
      "  File \"C:\\Users\\fakthar\\AppData\\Local\\anaconda3\\envs\\mytfenv\\lib\\site-packages\\IPython\\core\\interactiveshell.py\", line 2099, in showtraceback\n",
      "    stb = value._render_traceback_()\n",
      "AttributeError: 'TypeError' object has no attribute '_render_traceback_'\n",
      "\n",
      "During handling of the above exception, another exception occurred:\n",
      "\n",
      "Traceback (most recent call last):\n",
      "  File \"C:\\Users\\fakthar\\AppData\\Local\\anaconda3\\envs\\mytfenv\\lib\\site-packages\\IPython\\core\\interactiveshell.py\", line 3030, in _run_cell\n",
      "    return runner(coro)\n",
      "  File \"C:\\Users\\fakthar\\AppData\\Local\\anaconda3\\envs\\mytfenv\\lib\\site-packages\\IPython\\core\\async_helpers.py\", line 78, in _pseudo_sync_runner\n",
      "    coro.send(None)\n",
      "  File \"C:\\Users\\fakthar\\AppData\\Local\\anaconda3\\envs\\mytfenv\\lib\\site-packages\\IPython\\core\\interactiveshell.py\", line 3258, in run_cell_async\n",
      "    interactivity=interactivity, compiler=compiler, result=result)\n",
      "  File \"C:\\Users\\fakthar\\AppData\\Local\\anaconda3\\envs\\mytfenv\\lib\\site-packages\\IPython\\core\\interactiveshell.py\", line 3492, in run_ast_nodes\n",
      "    self.showtraceback()\n",
      "  File \"C:\\Users\\fakthar\\AppData\\Local\\anaconda3\\envs\\mytfenv\\lib\\site-packages\\IPython\\core\\interactiveshell.py\", line 2102, in showtraceback\n",
      "    value, tb, tb_offset=tb_offset)\n",
      "  File \"C:\\Users\\fakthar\\AppData\\Local\\anaconda3\\envs\\mytfenv\\lib\\site-packages\\IPython\\core\\ultratb.py\", line 1368, in structured_traceback\n",
      "    self, etype, value, tb, tb_offset, number_of_lines_of_context)\n",
      "  File \"C:\\Users\\fakthar\\AppData\\Local\\anaconda3\\envs\\mytfenv\\lib\\site-packages\\IPython\\core\\ultratb.py\", line 1268, in structured_traceback\n",
      "    self, etype, value, tb, tb_offset, number_of_lines_of_context\n",
      "  File \"C:\\Users\\fakthar\\AppData\\Local\\anaconda3\\envs\\mytfenv\\lib\\site-packages\\IPython\\core\\ultratb.py\", line 1143, in structured_traceback\n",
      "    chained_exceptions_tb_offset)\n",
      "  File \"C:\\Users\\fakthar\\AppData\\Local\\anaconda3\\envs\\mytfenv\\lib\\site-packages\\IPython\\core\\ultratb.py\", line 1082, in format_exception_as_a_whole\n",
      "    last_unique, recursion_repeat = find_recursion(orig_etype, evalue, records)\n",
      "  File \"C:\\Users\\fakthar\\AppData\\Local\\anaconda3\\envs\\mytfenv\\lib\\site-packages\\IPython\\core\\ultratb.py\", line 382, in find_recursion\n",
      "    return len(records), 0\n",
      "TypeError: object of type 'NoneType' has no len()\n",
      "\n",
      "During handling of the above exception, another exception occurred:\n",
      "\n",
      "Traceback (most recent call last):\n",
      "  File \"C:\\Users\\fakthar\\AppData\\Local\\anaconda3\\envs\\mytfenv\\lib\\site-packages\\IPython\\core\\interactiveshell.py\", line 2099, in showtraceback\n",
      "    stb = value._render_traceback_()\n",
      "AttributeError: 'TypeError' object has no attribute '_render_traceback_'\n",
      "\n",
      "During handling of the above exception, another exception occurred:\n",
      "\n",
      "Traceback (most recent call last):\n",
      "  File \"C:\\Users\\fakthar\\AppData\\Local\\anaconda3\\envs\\mytfenv\\lib\\site-packages\\IPython\\core\\ultratb.py\", line 1101, in get_records\n",
      "    return _fixed_getinnerframes(etb, number_of_lines_of_context, tb_offset)\n",
      "  File \"C:\\Users\\fakthar\\AppData\\Local\\anaconda3\\envs\\mytfenv\\lib\\site-packages\\IPython\\core\\ultratb.py\", line 248, in wrapped\n",
      "    return f(*args, **kwargs)\n",
      "  File \"C:\\Users\\fakthar\\AppData\\Local\\anaconda3\\envs\\mytfenv\\lib\\site-packages\\IPython\\core\\ultratb.py\", line 281, in _fixed_getinnerframes\n",
      "    records = fix_frame_records_filenames(inspect.getinnerframes(etb, context))\n",
      "  File \"C:\\Users\\fakthar\\AppData\\Local\\anaconda3\\envs\\mytfenv\\lib\\inspect.py\", line 1500, in getinnerframes\n",
      "    frameinfo = (tb.tb_frame,) + getframeinfo(tb, context)\n",
      "  File \"C:\\Users\\fakthar\\AppData\\Local\\anaconda3\\envs\\mytfenv\\lib\\inspect.py\", line 1458, in getframeinfo\n",
      "    filename = getsourcefile(frame) or getfile(frame)\n",
      "  File \"C:\\Users\\fakthar\\AppData\\Local\\anaconda3\\envs\\mytfenv\\lib\\inspect.py\", line 696, in getsourcefile\n",
      "    if getattr(getmodule(object, filename), '__loader__', None) is not None:\n",
      "  File \"C:\\Users\\fakthar\\AppData\\Local\\anaconda3\\envs\\mytfenv\\lib\\inspect.py\", line 733, in getmodule\n",
      "    if ismodule(module) and hasattr(module, '__file__'):\n",
      "  File \"C:\\Users\\fakthar\\AppData\\Local\\anaconda3\\envs\\mytfenv\\lib\\site-packages\\tensorflow\\__init__.py\", line 50, in __getattr__\n",
      "    module = self._load()\n",
      "  File \"C:\\Users\\fakthar\\AppData\\Local\\anaconda3\\envs\\mytfenv\\lib\\site-packages\\tensorflow\\__init__.py\", line 44, in _load\n",
      "    module = _importlib.import_module(self.__name__)\n",
      "  File \"C:\\Users\\fakthar\\AppData\\Local\\anaconda3\\envs\\mytfenv\\lib\\importlib\\__init__.py\", line 127, in import_module\n",
      "    return _bootstrap._gcd_import(name[level:], package, level)\n",
      "  File \"<frozen importlib._bootstrap>\", line 1006, in _gcd_import\n",
      "  File \"<frozen importlib._bootstrap>\", line 983, in _find_and_load\n",
      "  File \"<frozen importlib._bootstrap>\", line 953, in _find_and_load_unlocked\n",
      "  File \"<frozen importlib._bootstrap>\", line 219, in _call_with_frames_removed\n",
      "  File \"<frozen importlib._bootstrap>\", line 1006, in _gcd_import\n",
      "  File \"<frozen importlib._bootstrap>\", line 983, in _find_and_load\n",
      "  File \"<frozen importlib._bootstrap>\", line 967, in _find_and_load_unlocked\n",
      "  File \"<frozen importlib._bootstrap>\", line 677, in _load_unlocked\n",
      "  File \"<frozen importlib._bootstrap_external>\", line 728, in exec_module\n",
      "  File \"<frozen importlib._bootstrap>\", line 219, in _call_with_frames_removed\n",
      "  File \"C:\\Users\\fakthar\\AppData\\Local\\anaconda3\\envs\\mytfenv\\lib\\site-packages\\tensorflow_core\\__init__.py\", line 42, in <module>\n",
      "    from . _api.v2 import audio\n",
      "  File \"C:\\Users\\fakthar\\AppData\\Local\\anaconda3\\envs\\mytfenv\\lib\\site-packages\\tensorflow_core\\_api\\v2\\audio\\__init__.py\", line 10, in <module>\n",
      "    from tensorflow.python.ops.gen_audio_ops import decode_wav\n",
      "  File \"C:\\Users\\fakthar\\AppData\\Local\\anaconda3\\envs\\mytfenv\\lib\\site-packages\\tensorflow_core\\python\\ops\\gen_audio_ops.py\", line 10, in <module>\n",
      "    from tensorflow.python.eager import context as _context\n",
      "  File \"C:\\Users\\fakthar\\AppData\\Local\\anaconda3\\envs\\mytfenv\\lib\\site-packages\\tensorflow_core\\python\\eager\\context.py\", line 29, in <module>\n",
      "    from tensorflow.core.protobuf import config_pb2\n",
      "  File \"C:\\Users\\fakthar\\AppData\\Local\\anaconda3\\envs\\mytfenv\\lib\\site-packages\\tensorflow_core\\core\\protobuf\\config_pb2.py\", line 16, in <module>\n",
      "    from tensorflow.core.framework import cost_graph_pb2 as tensorflow_dot_core_dot_framework_dot_cost__graph__pb2\n",
      "  File \"C:\\Users\\fakthar\\AppData\\Local\\anaconda3\\envs\\mytfenv\\lib\\site-packages\\tensorflow_core\\core\\framework\\cost_graph_pb2.py\", line 16, in <module>\n",
      "    from tensorflow.core.framework import tensor_shape_pb2 as tensorflow_dot_core_dot_framework_dot_tensor__shape__pb2\n",
      "  File \"C:\\Users\\fakthar\\AppData\\Local\\anaconda3\\envs\\mytfenv\\lib\\site-packages\\tensorflow_core\\core\\framework\\tensor_shape_pb2.py\", line 42, in <module>\n",
      "    serialized_options=None, file=DESCRIPTOR),\n",
      "  File \"C:\\Users\\fakthar\\AppData\\Local\\anaconda3\\envs\\mytfenv\\lib\\site-packages\\google\\protobuf\\descriptor.py\", line 561, in __new__\n",
      "    _message.Message._CheckCalledFromGeneratedFile()\n",
      "TypeError: Descriptors cannot not be created directly.\n",
      "If this call came from a _pb2.py file, your generated code is out of date and must be regenerated with protoc >= 3.19.0.\n",
      "If you cannot immediately regenerate your protos, some other possible workarounds are:\n",
      " 1. Downgrade the protobuf package to 3.20.x or lower.\n",
      " 2. Set PROTOCOL_BUFFERS_PYTHON_IMPLEMENTATION=python (but this will use pure-Python parsing and will be much slower).\n",
      "\n",
      "More information: https://developers.google.com/protocol-buffers/docs/news/2022-05-06#python-updates\n"
     ]
    }
   ],
   "source": [
    "import tensorflow as tf"
   ]
  },
  {
   "cell_type": "code",
   "execution_count": null,
   "id": "9f64eaf6",
   "metadata": {},
   "outputs": [],
   "source": []
  }
 ],
 "metadata": {
  "kernelspec": {
   "display_name": "Python 3 (ipykernel)",
   "language": "python",
   "name": "python3"
  },
  "language_info": {
   "codemirror_mode": {
    "name": "ipython",
    "version": 3
   },
   "file_extension": ".py",
   "mimetype": "text/x-python",
   "name": "python",
   "nbconvert_exporter": "python",
   "pygments_lexer": "ipython3",
   "version": "3.7.1"
  }
 },
 "nbformat": 4,
 "nbformat_minor": 5
}
